Workbook
Name Slicer_Sales_Channel: #N/A
Name Slicer_Order_Status: #N/A
Name Slicer_Customer_Segment: #N/A

Sheet Customers_Raw
A1: Customer_ID | B1: Customer_Name | C1: City | D1: Signup_Date | E1: Customer_Segment
A2: C10001 | B2: Rahul Kumar | C2: Hyderabad | D2: 45815 | E2: Small Business
A3: C10002 | B3: Kavya Arora | C3: Amritsar | D3: 45692 | E3: Corporate
A4: C10003 | B4: Vikram Khanna | C4: Amritsar | D4: 45996 | E4: Corporate
A5: C10004 | B5: Rahul Chawla | C5: Delhi | D5: 45313 | E5: Consumer
A6: C10005 | B6: Pooja Mehta | C6: Jaipur | D6: 45765 | E6: Consumer
A7: C10006 | B7: Diya Arora | C7: Chandigarh | D7: 45411 | E7: Consumer
A8: C10007 | B8: Arjun Kapoor | C8: Jaipur | D8: 45501 | E8: Corporate
A9: C10008 | B9: Aditya Malhotra | C9: Mumbai | D9: 45597 | E9: Consumer
A10: C10009 | B10: Vivaan Kapoor | C10: Chandigarh | D10: 45561 | E10: Consumer
A11: C10010 | B11: Isha Joshi | C11: Hyderabad | D11: 45995 | E11: Small Business
A12: C10011 | B12: Karan Verma | C12: Mumbai | D12: 45978 | E12: Consumer
A13: C10012 | B13: Aarav Sethi | C13: Pune | D13: 45576 | E13: Consumer
... A24: C10023 | B24: Neha Kumar | C24: Mumbai | D24: 45750 | E24: Small Business
A25: C10024 | C25: Amritsar | D25: 45861 | E25: Corporate
A26: C10025 | B26: Nikhil Chawla | C26: Gurugram | D26: 45829 | E26: Consumer
A27: C10026 | B27: Vivaan Kumar | C27: Noida | D27: 45773 | E27: Consumer
A28: C10027 | B28: Kavya Sethi | C28: Pune | D28: 45721 | E28: Consumer
A29: C10028 | B29: Rahul Sethi | C29: Chandigarh | D29: 45576 | E29: Consumer
A30: C10029 | B30: Vikram Mishra | C30: Gurugram | D30: 45807 | E30: Consumer
A31: C10030 | B31: Aditya Joshi | C31: Noida | D31: 45390 | E31: Consumer
A32: C10031 | B32: Riya Kumar | C32: Ludhiana | D32: 45688 | E32: Consumer
A33: C10032 | B33: Neha Kapoor | C33: Jaipur | D33: 45780 | E33: Consumer
A34: C10033 | B34: Arjun Verma | C34: Delhi | D34: 45330 | E34: Consumer
A35: C10034 | B35: Karan Malhotra | C35: Pune | D35: 45562 | E35: Consumer
A36: C10035 | B36: Ananya Kumar | C36: Delhi | D36: 45448 | E36: Corporate
A37: C10036 | B37: Neha Chawla | C37: Pune | D37: 45366 | E37: Consumer
... A601: C10600 | B601: Diya Sethi | C601: Chandigarh | D601: 45839 | E601: Consumer

Sheet Orders_Raw
A1: Order_ID | B1: Customer_ID | C1: Order_Date | D1: Order_Status | E1: Sales_Channel | F1: Payment_Method | G1: Customer_Segment
A2: O50001 | B2: C10139 | C2: 45692 | D2: Shipped | E2: Website | F2: Net Banking | G2: =_xlfn.XLOOKUP(Orders_Raw!B2,Customers_Raw!A:A,Customers_Raw!E:E) -> Consumer
A3: O50002 | B3: C10359 | C3: 45840 | D3: Shipped | E3: Website | F3: Credit Card | G3: =_xlfn.XLOOKUP(Orders_Raw!B3,Customers_Raw!A:A,Customers_Raw!E:E) -> Consumer
A4: O50003 | B4: C10499 | C4: 45927 | D4: Shipped | E4: Website | F4: UPI | G4: =_xlfn.XLOOKUP(Orders_Raw!B4,Customers_Raw!A:A,Customers_Raw!E:E) -> Consumer
A5: O50004 | B5: C10385 | C5: 46015 | D5: Delivered | E5: Mobile App | F5: Credit Card | G5: =_xlfn.XLOOKUP(Orders_Raw!B5,Customers_Raw!A:A,Customers_Raw!E:E) -> Consumer
A6: O50005 | B6: C10280 | C6: 45757 | D6: Delivered | E6: Marketplace | F6: Net Banking | G6: =_xlfn.XLOOKUP(Orders_Raw!B6,Customers_Raw!A:A,Customers_Raw!E:E) -> Corporate
A7: O50006 | B7: C10483 | C7: 45664 | D7: Delivered | E7: Mobile App | F7: Debit Card | G7: =_xlfn.XLOOKUP(Orders_Raw!B7,Customers_Raw!A:A,Customers_Raw!E:E) -> Corporate
A8: O50007 | B8: C10111 | C8: 45687 | D8: Cancelled | E8: Website | F8: Debit Card | G8: =_xlfn.XLOOKUP(Orders_Raw!B8,Customers_Raw!A:A,Customers_Raw!E:E) -> Corporate
A9: O50008 | B9: C10139 | C9: 45962 | D9: Delivered | E9: Mobile App | F9: UPI | G9: =_xlfn.XLOOKUP(Orders_Raw!B9,Customers_Raw!A:A,Customers_Raw!E:E) -> Consumer
A10: O50009 | B10: C10435 | C10: 45801 | D10: Delivered | E10: Mobile App | F10: COD | G10: =_xlfn.XLOOKUP(Orders_Raw!B10,Customers_Raw!A:A,Customers_Raw!E:E) -> Consumer
A11: O50010 | B11: C10509 | C11: 45768 | D11: Delivered | E11: Website | F11: Credit Card | G11: =_xlfn.XLOOKUP(Orders_Raw!B11,Customers_Raw!A:A,Customers_Raw!E:E) -> Corporate
A12: O50011 | B12: C10273 | C12: 45889 | D12: Delivered | E12: Marketplace | F12: Debit Card | G12: =_xlfn.XLOOKUP(Orders_Raw!B12,Customers_Raw!A:A,Customers_Raw!E:E) -> Corporate
A13: O50012 | B13: C10099 | C13: 45836 | D13: Delivered | E13: Website | F13: UPI | G13: =_xlfn.XLOOKUP(Orders_Raw!B13,Customers_Raw!A:A,Customers_Raw!E:E) -> Corporate
... A2501: O52500 | B2501: C10492 | C2501: 45892 | D2501: Delivered | E2501: Mobile App | F2501: Credit Card | G2501: =_xlfn.XLOOKUP(Orders_Raw!B2501,Customers_Raw!A:A,Customers_Raw!E:E) -> Corporate

Sheet Order_Items_Raw
A1: Order_ID | B1: Product_ID | C1: Quantity | D1: Line_Revenue | E1: Unit_Cost | F1: Gross_Profit | G1: Sales_Channel | H1: Category | I1: Customer_Segment | J1: Order_Date | K1: Order_Month | L1: Order Status | M1: Customer Segment | N1: Order_Flag
A2: O51025 | B2: P1001 | C2: 3 | D2: 18176.21 | E2: =_xlfn.XLOOKUP(Order_Items_Raw!B21,Products_Raw!A:A,Products_Raw!D:D) -> 10361.65 | F2: =D2-(C2*E2) -> -12908.74 | G2: =PROPER(TRIM(CLEAN(_xlfn.XLOOKUP(Order_Items_Raw!A21,Orders_Raw!A:A,Orders_Raw!E:E)))) -> Website | H2: =_xlfn.XLOOKUP(B2,Products_Raw!A:A,Products_Raw!C:C) -> Sports | I2: =_xlfn.XLOOKUP(_xlfn.XLOOKUP(A2,Orders_Raw!A:A,Orders_Raw!B:B),Customers_Raw!A:A,Customers_Raw!E:E) -> Consumer | J2: =_xlfn.XLOOKUP(Order_Items_Raw!A21,Orders_Raw!A:A,Orders_Raw!C:C) -> 45762 | K2: Apr | L2: =_xlfn.XLOOKUP(A2,Orders_Raw!A:A,Orders_Raw!D:D) -> Delivered | M2: =_xlfn.XLOOKUP(_xlfn.XLOOKUP(A2,Orders_Raw!A:A,Orders_Raw!B:B),Customers_Raw!A:A,Customers_Raw!E:E) -> Consumer | N2: =IF(COUNTIF($A$2:A2,A2)=1,1,0) -> 1
A3: O52146 | B3: P1001 | C3: 1 | D3: 7201.05 | E3: =_xlfn.XLOOKUP(Order_Items_Raw!B38,Products_Raw!A:A,Products_Raw!D:D) -> 9148.31 | F3: =D3-(C3*E3) -> -1947.26 | G3: =PROPER(TRIM(CLEAN(_xlfn.XLOOKUP(Order_Items_Raw!A38,Orders_Raw!A:A,Orders_Raw!E:E)))) -> Website | H3: =_xlfn.XLOOKUP(B3,Products_Raw!A:A,Products_Raw!C:C) -> Sports | I3: =_xlfn.XLOOKUP(_xlfn.XLOOKUP(A3,Orders_Raw!A:A,Orders_Raw!B:B),Customers_Raw!A:A,Customers_Raw!E:E) -> Consumer | J3: =_xlfn.XLOOKUP(Order_Items_Raw!A38,Orders_Raw!A:A,Orders_Raw!C:C) -> 45771 | K3: Apr | L3: =_xlfn.XLOOKUP(A3,Orders_Raw!A:A,Orders_Raw!D:D) -> Processing | M3: =_xlfn.XLOOKUP(_xlfn.XLOOKUP(A3,Orders_Raw!A:A,Orders_Raw!B:B),Customers_Raw!A:A,Customers_Raw!E:E) -> Consumer | N3: =IF(COUNTIF($A$2:A3,A3)=1,1,0) -> 1
A4: O51186 | B4: P1002 | C4: 4 | D4: 54525.46 | E4: =_xlfn.XLOOKUP(Order_Items_Raw!B65,Products_Raw!A:A,Products_Raw!D:D) -> 4806.74 | F4: =D4-(C4*E4) -> 35298.5 | G4: =PROPER(TRIM(CLEAN(_xlfn.XLOOKUP(Order_Items_Raw!A65,Orders_Raw!A:A,Orders_Raw!E:E)))) -> Mobile App | H4: =_xlfn.XLOOKUP(B4,Products_Raw!A:A,Products_Raw!C:C) -> Sports | I4: =_xlfn.XLOOKUP(_xlfn.XLOOKUP(A4,Orders_Raw!A:A,Orders_Raw!B:B),Customers_Raw!A:A,Customers_Raw!E:E) -> Small Business | J4: =_xlfn.XLOOKUP(Order_Items_Raw!A65,Orders_Raw!A:A,Orders_Raw!C:C) -> 45754 | K4: Apr | L4: =_xlfn.XLOOKUP(A4,Orders_Raw!A:A,Orders_Raw!D:D) -> Delivered | M4: =_xlfn.XLOOKUP(_xlfn.XLOOKUP(A4,Orders_Raw!A:A,Orders_Raw!B:B),Customers_Raw!A:A,Customers_Raw!E:E) -> Small Business | N4: =IF(COUNTIF($A$2:A4,A4)=1,1,0) -> 1
A5: O51398 | B5: P1002 | C5: 2 | D5: 24468.58 | E5: =_xlfn.XLOOKUP(Order_Items_Raw!B72,Products_Raw!A:A,Products_Raw!D:D) -> 6213.42 | F5: =D5-(C5*E5) -> 12041.74 | G5: =PROPER(TRIM(CLEAN(_xlfn.XLOOKUP(Order_Items_Raw!A72,Orders_Raw!A:A,Orders_Raw!E:E)))) -> Marketplace | H5: =_xlfn.XLOOKUP(B5,Products_Raw!A:A,Products_Raw!C:C) -> Sports | I5: =_xlfn.XLOOKUP(_xlfn.XLOOKUP(A5,Orders_Raw!A:A,Orders_Raw!B:B),Customers_Raw!A:A,Customers_Raw!E:E) -> Consumer | J5: =_xlfn.XLOOKUP(Order_Items_Raw!A72,Orders_Raw!A:A,Orders_Raw!C:C) -> 45757 | K5: Apr | L5: =_xlfn.XLOOKUP(A5,Orders_Raw!A:A,Orders_Raw!D:D) -> Delivered | M5: =_xlfn.XLOOKUP(_xlfn.XLOOKUP(A5,Orders_Raw!A:A,Orders_Raw!B:B),Customers_Raw!A:A,Customers_Raw!E:E) -> Consumer | N5: =IF(COUNTIF($A$2:A5,A5)=1,1,0) -> 1
A6: O52459 | B6: P1002 | C6: 2 | D6: 29750.74 | E6: =_xlfn.XLOOKUP(Order_Items_Raw!B89,Products_Raw!A:A,Products_Raw!D:D) -> 680.62 | F6: =D6-(C6*E6) -> 28389.5 | G6: =PROPER(TRIM(CLEAN(_xlfn.XLOOKUP(Order_Items_Raw!A89,Orders_Raw!A:A,Orders_Raw!E:E)))) -> Mobile App | H6: =_xlfn.XLOOKUP(B6,Products_Raw!A:A,Products_Raw!C:C) -> Sports | I6: =_xlfn.XLOOKUP(_xlfn.XLOOKUP(A6,Orders_Raw!A:A,Orders_Raw!B:B),Customers_Raw!A:A,Customers_Raw!E:E) -> Consumer | J6: =_xlfn.XLOOKUP(Order_Items_Raw!A89,Orders_Raw!A:A,Orders_Raw!C:C) -> 45751 | K6: Apr | L6: =_xlfn.XLOOKUP(A6,Orders_Raw!A:A,Orders_Raw!D:D) -> Delivered | M6: =_xlfn.XLOOKUP(_xlfn.XLOOKUP(A6,Orders_Raw!A:A,Orders_Raw!B:B),Customers_Raw!A:A,Customers_Raw!E:E) -> Consumer | N6: =IF(COUNTIF($A$2:A6,A6)=1,1,0) -> 1
A7: O50090 | B7: P1003 | C7: 3 | D7: 18086.3 | E7: =_xlfn.XLOOKUP(Order_Items_Raw!B90,Products_Raw!A:A,Products_Raw!D:D) -> 680.62 | F7: =D7-(C7*E7) -> 16044.44 | G7: =PROPER(TRIM(CLEAN(_xlfn.XLOOKUP(Order_Items_Raw!A90,Orders_Raw!A:A,Orders_Raw!E:E)))) -> Mobile App | H7: =_xlfn.XLOOKUP(B7,Products_Raw!A:A,Products_Raw!C:C) -> Sports | I7: =_xlfn.XLOOKUP(_xlfn.XLOOKUP(A7,Orders_Raw!A:A,Orders_Raw!B:B),Customers_Raw!A:A,Customers_Raw!E:E) -> Corporate | J7: =_xlfn.XLOOKUP(Order_Items_Raw!A90,Orders_Raw!A:A,Orders_Raw!C:C) -> 45765 | K7: Apr | L7: =_xlfn.XLOOKUP(A7,Orders_Raw!A:A,Orders_Raw!D:D) -> Delivered | M7: =_xlfn.XLOOKUP(_xlfn.XLOOKUP(A7,Orders_Raw!A:A,Orders_Raw!B:B),Customers_Raw!A:A,Customers_Raw!E:E) -> Corporate | N7: =IF(COUNTIF($A$2:A7,A7)=1,1,0) -> 1
A8: O50207 | B8: P1003 | C8: 1 | D8: 7413.85 | E8: =_xlfn.XLOOKUP(Order_Items_Raw!B92,Products_Raw!A:A,Products_Raw!D:D) -> 11367.74 | F8: =D8-(C8*E8) -> -3953.89 | G8: =PROPER(TRIM(CLEAN(_xlfn.XLOOKUP(Order_Items_Raw!A92,Orders_Raw!A:A,Orders_Raw!E:E)))) -> Mobile App | H8: =_xlfn.XLOOKUP(B8,Products_Raw!A:A,Products_Raw!C:C) -> Sports | I8: =_xlfn.XLOOKUP(_xlfn.XLOOKUP(A8,Orders_Raw!A:A,Orders_Raw!B:B),Customers_Raw!A:A,Customers_Raw!E:E) -> Consumer | J8: =_xlfn.XLOOKUP(Order_Items_Raw!A92,Orders_Raw!A:A,Orders_Raw!C:C) -> 45755 | K8: Apr | L8: =_xlfn.XLOOKUP(A8,Orders_Raw!A:A,Orders_Raw!D:D) -> Delivered | M8: =_xlfn.XLOOKUP(_xlfn.XLOOKUP(A8,Orders_Raw!A:A,Orders_Raw!B:B),Customers_Raw!A:A,Customers_Raw!E:E) -> Consumer | N8: =IF(COUNTIF($A$2:A8,A8)=1,1,0) -> 1
A9: O51279 | B9: P1003 | C9: 4 | D9: 31497.12 | E9: =_xlfn.XLOOKUP(Order_Items_Raw!B112,Products_Raw!A:A,Products_Raw!D:D) -> 229.52 | F9: =D9-(C9*E9) -> 30579.04 | G9: =PROPER(TRIM(CLEAN(_xlfn.XLOOKUP(Order_Items_Raw!A112,Orders_Raw!A:A,Orders_Raw!E:E)))) -> Marketplace | H9: =_xlfn.XLOOKUP(B9,Products_Raw!A:A,Products_Raw!C:C) -> Sports | I9: =_xlfn.XLOOKUP(_xlfn.XLOOKUP(A9,Orders_Raw!A:A,Orders_Raw!B:B),Customers_Raw!A:A,Customers_Raw!E:E) -> Consumer | J9: =_xlfn.XLOOKUP(Order_Items_Raw!A112,Orders_Raw!A:A,Orders_Raw!C:C) -> 45751 | K9: Apr | L9: =_xlfn.XLOOKUP(A9,Orders_Raw!A:A,Orders_Raw!D:D) -> Delivered | M9: =_xlfn.XLOOKUP(_xlfn.XLOOKUP(A9,Orders_Raw!A:A,Orders_Raw!B:B),Customers_Raw!A:A,Customers_Raw!E:E) -> Consumer | N9: =IF(COUNTIF($A$2:A9,A9)=1,1,0) -> 1
A10: O51549 | B10: P1003 | C10: 2 | D10: 11986.74 | E10: =_xlfn.XLOOKUP(Order_Items_Raw!B115,Products_Raw!A:A,Products_Raw!D:D) -> 9531.89 | F10: =D10-(C10*E10) -> -7077.04 | G10: =PROPER(TRIM(CLEAN(_xlfn.XLOOKUP(Order_Items_Raw!A115,Orders_Raw!A:A,Orders_Raw!E:E)))) -> Marketplace | H10: =_xlfn.XLOOKUP(B10,Products_Raw!A:A,Products_Raw!C:C) -> Sports | I10: =_xlfn.XLOOKUP(_xlfn.XLOOKUP(A10,Orders_Raw!A:A,Orders_Raw!B:B),Customers_Raw!A:A,Customers_Raw!E:E) -> Small Business | J10: =_xlfn.XLOOKUP(Order_Items_Raw!A115,Orders_Raw!A:A,Orders_Raw!C:C) -> 45754 | K10: Apr | L10: =_xlfn.XLOOKUP(A10,Orders_Raw!A:A,Orders_Raw!D:D) -> Delivered | M10: =_xlfn.XLOOKUP(_xlfn.XLOOKUP(A10,Orders_Raw!A:A,Orders_Raw!B:B),Customers_Raw!A:A,Customers_Raw!E:E) -> Small Business | N10: =IF(COUNTIF($A$2:A10,A10)=1,1,0) -> 1
A11: O51620 | B11: P1003 | C11: 4 | D11: 31246.92 | E11: =_xlfn.XLOOKUP(Order_Items_Raw!B121,Products_Raw!A:A,Products_Raw!D:D) -> 7212.47 | F11: =D11-(C11*E11) -> 2397.04 | G11: =PROPER(TRIM(CLEAN(_xlfn.XLOOKUP(Order_Items_Raw!A121,Orders_Raw!A:A,Orders_Raw!E:E)))) -> Mobile App | H11: =_xlfn.XLOOKUP(B11,Products_Raw!A:A,Products_Raw!C:C) -> Sports | I11: =_xlfn.XLOOKUP(_xlfn.XLOOKUP(A11,Orders_Raw!A:A,Orders_Raw!B:B),Customers_Raw!A:A,Customers_Raw!E:E) -> Consumer | J11: =_xlfn.XLOOKUP(Order_Items_Raw!A121,Orders_Raw!A:A,Orders_Raw!C:C) -> 45769 | K11: Apr | L11: =_xlfn.XLOOKUP(A11,Orders_Raw!A:A,Orders_Raw!D:D) -> Cancelled | M11: =_xlfn.XLOOKUP(_xlfn.XLOOKUP(A11,Orders_Raw!A:A,Orders_Raw!B:B),Customers_Raw!A:A,Customers_Raw!E:E) -> Consumer | N11: =IF(COUNTIF($A$2:A11,A11)=1,1,0) -> 1
A12: O51717 | B12: P1003 | C12: 3 | D12: 18926.73 | E12: =_xlfn.XLOOKUP(Order_Items_Raw!B125,Products_Raw!A:A,Products_Raw!D:D) -> 1349.93 | F12: =D12-(C12*E12) -> 14876.94 | G12: =PROPER(TRIM(CLEAN(_xlfn.XLOOKUP(Order_Items_Raw!A125,Orders_Raw!A:A,Orders_Raw!E:E)))) -> Website | H12: =_xlfn.XLOOKUP(B12,Products_Raw!A:A,Products_Raw!C:C) -> Sports | I12: =_xlfn.XLOOKUP(_xlfn.XLOOKUP(A12,Orders_Raw!A:A,Orders_Raw!B:B),Customers_Raw!A:A,Customers_Raw!E:E) -> Corporate | J12: =_xlfn.XLOOKUP(Order_Items_Raw!A125,Orders_Raw!A:A,Orders_Raw!C:C) -> 45757 | K12: Apr | L12: =_xlfn.XLOOKUP(A12,Orders_Raw!A:A,Orders_Raw!D:D) -> Shipped | M12: =_xlfn.XLOOKUP(_xlfn.XLOOKUP(A12,Orders_Raw!A:A,Orders_Raw!B:B),Customers_Raw!A:A,Customers_Raw!E:E) -> Corporate | N12: =IF(COUNTIF($A$2:A12,A12)=1,1,0) -> 1
A13: O51806 | B13: P1003 | C13: 2 | D13: 12184.13 | E13: =_xlfn.XLOOKUP(Order_Items_Raw!B127,Products_Raw!A:A,Products_Raw!D:D) -> 1349.93 | F13: =D13-(C13*E13) -> 9484.27 | G13: =PROPER(TRIM(CLEAN(_xlfn.XLOOKUP(Order_Items_Raw!A127,Orders_Raw!A:A,Orders_Raw!E:E)))) -> Website | H13: =_xlfn.XLOOKUP(B13,Products_Raw!A:A,Products_Raw!C:C) -> Sports | I13: =_xlfn.XLOOKUP(_xlfn.XLOOKUP(A13,Orders_Raw!A:A,Orders_Raw!B:B),Customers_Raw!A:A,Customers_Raw!E:E) -> Consumer | J13: =_xlfn.XLOOKUP(Order_Items_Raw!A127,Orders_Raw!A:A,Orders_Raw!C:C) -> 45764 | K13: Apr | L13: =_xlfn.XLOOKUP(A13,Orders_Raw!A:A,Orders_Raw!D:D) -> Delivered | M13: =_xlfn.XLOOKUP(_xlfn.XLOOKUP(A13,Orders_Raw!A:A,Orders_Raw!B:B),Customers_Raw!A:A,Customers_Raw!E:E) -> Consumer | N13: =IF(COUNTIF($A$2:A13,A13)=1,1,0) -> 1
A14: O50152 | B14: P1004 | C14: 1 | D14: 1748.61 | E14: =_xlfn.XLOOKUP(Order_Items_Raw!B141,Products_Raw!A:A,Products_Raw!D:D) -> 6443.36 | F14: =D14-(C14*E14) -> -4694.75 | G14: =PROPER(TRIM(CLEAN(_xlfn.XLOOKUP(Order_Items_Raw!A141,Orders_Raw!A:A,Orders_Raw!E:E)))) -> Mobile App | H14: =_xlfn.XLOOKUP(B14,Products_Raw!A:A,Products_Raw!C:C) -> Beauty | I14: =_xlfn.XLOOKUP(_xlfn.XLOOKUP(A14,Orders_Raw!A:A,Orders_Raw!B:B),Customers_Raw!A:A,Customers_Raw!E:E) -> Consumer | J14: =_xlfn.XLOOKUP(Order_Items_Raw!A141,Orders_Raw!A:A,Orders_Raw!C:C) -> 45773 | K14: Apr | L14: =_xlfn.XLOOKUP(A14,Orders_Raw!A:A,Orders_Raw!D:D) -> Delivered | M14: =_xlfn.XLOOKUP(_xlfn.XLOOKUP(A14,Orders_Raw!A:A,Orders_Raw!B:B),Customers_Raw!A:A,Customers_Raw!E:E) -> Consumer | N14: =IF(COUNTIF($A$2:A14,A14)=1,1,0) -> 1
A15: O50310 | B15: P1004 | C15: 2 | D15: 2617.46 | E15: =_xlfn.XLOOKUP(Order_Items_Raw!B145,Products_Raw!A:A,Products_Raw!D:D) -> 10124.42 | F15: =D15-(C15*E15) -> -17631.38 | G15: =PROPER(TRIM(CLEAN(_xlfn.XLOOKUP(Order_Items_Raw!A145,Orders_Raw!A:A,Orders_Raw!E:E)))) -> Mobile App | H15: =_xlfn.XLOOKUP(B15,Products_Raw!A:A,Products_Raw!C:C) -> Beauty | I15: =_xlfn.XLOOKUP(_xlfn.XLOOKUP(A15,Orders_Raw!A:A,Orders_Raw!B:B),Customers_Raw!A:A,Customers_Raw!E:E) -> Small Business | J15: =_xlfn.XLOOKUP(Order_Items_Raw!A145,Orders_Raw!A:A,Orders_Raw!C:C) -> 45771 | K15: Apr | L15: =_xlfn.XLOOKUP(A15,Orders_Raw!A:A,Orders_Raw!D:D) -> Delivered | M15: =_xlfn.XLOOKUP(_xlfn.XLOOKUP(A15,Orders_Raw!A:A,Orders_Raw!B:B),Customers_Raw!A:A,Customers_Raw!E:E) -> Small Business | N15: =IF(COUNTIF($A$2:A15,A15)=1,1,0) -> 1
A16: O51177 | B16: P1004 | C16: 1 | D16: 1455.44 | E16: =_xlfn.XLOOKUP(Order_Items_Raw!B158,Products_Raw!A:A,Products_Raw!D:D) -> 1397.32 | F16: =D16-(C16*E16) -> 58.12 | G16: =PROPER(TRIM(CLEAN(_xlfn.XLOOKUP(Order_Items_Raw!A158,Orders_Raw!A:A,Orders_Raw!E:E)))) -> Mobile App | H16: =_xlfn.XLOOKUP(B16,Products_Raw!A:A,Products_Raw!C:C) -> Beauty | I16: =_xlfn.XLOOKUP(_xlfn.XLOOKUP(A16,Orders_Raw!A:A,Orders_Raw!B:B),Customers_Raw!A:A,Customers_Raw!E:E) -> Consumer | J16: =_xlfn.XLOOKUP(Order_Items_Raw!A158,Orders_Raw!A:A,Orders_Raw!C:C) -> 45774 | K16: Apr | L16: =_xlfn.XLOOKUP(A16,Orders_Raw!A:A,Orders_Raw!D:D) -> Delivered | M16: =_xlfn.XLOOKUP(_xlfn.XLOOKUP(A16,Orders_Raw!A:A,Orders_Raw!B:B),Customers_Raw!A:A,Customers_Raw!E:E) -> Consumer | N16: =IF(COUNTIF($A$2:A16,A16)=1,1,0) -> 1
A17: O52217 | B17: P1004 | C17: 3 | D17: 4073.11 | E17: =_xlfn.XLOOKUP(Order_Items_Raw!B176,Products_Raw!A:A,Products_Raw!D:D) -> 2857.57 | F17: =D17-(C17*E17) -> -4499.6 | G17: =PROPER(TRIM(CLEAN(_xlfn.XLOOKUP(Order_Items_Raw!A176,Orders_Raw!A:A,Orders_Raw!E:E)))) -> Mobile App | H17: =_xlfn.XLOOKUP(B17,Products_Raw!A:A,Products_Raw!C:C) -> Beauty | I17: =_xlfn.XLOOKUP(_xlfn.XLOOKUP(A17,Orders_Raw!A:A,Orders_Raw!B:B),Customers_Raw!A:A,Customers_Raw!E:E) -> Consumer | J17: =_xlfn.XLOOKUP(Order_Items_Raw!A176,Orders_Raw!A:A,Orders_Raw!C:C) -> 45771 | K17: Apr | L17: =_xlfn.XLOOKUP(A17,Orders_Raw!A:A,Orders_Raw!D:D) -> Delivered | M17: =_xlfn.XLOOKUP(_xlfn.XLOOKUP(A17,Orders_Raw!A:A,Orders_Raw!B:B),Customers_Raw!A:A,Customers_Raw!E:E) -> Consumer | N17: =IF(COUNTIF($A$2:A17,A17)=1,1,0) -> 1
A18: O50871 | B18: P1005 | C18: 4 | D18: 42137.63 | E18: =_xlfn.XLOOKUP(Order_Items_Raw!B202,Products_Raw!A:A,Products_Raw!D:D) -> 11118.8 | F18: =D18-(C18*E18) -> -2337.57 | G18: =PROPER(TRIM(CLEAN(_xlfn.XLOOKUP(Order_Items_Raw!A202,Orders_Raw!A:A,Orders_Raw!E:E)))) -> Marketplace | H18: =_xlfn.XLOOKUP(B18,Products_Raw!A:A,Products_Raw!C:C) -> Sports | I18: =_xlfn.XLOOKUP(_xlfn.XLOOKUP(A18,Orders_Raw!A:A,Orders_Raw!B:B),Customers_Raw!A:A,Customers_Raw!E:E) -> Consumer | J18: =_xlfn.XLOOKUP(Order_Items_Raw!A202,Orders_Raw!A:A,Orders_Raw!C:C) -> 45773 | K18: Apr | L18: =_xlfn.XLOOKUP(A18,Orders_Raw!A:A,Orders_Raw!D:D) -> Shipped | M18: =_xlfn.XLOOKUP(_xlfn.XLOOKUP(A18,Orders_Raw!A:A,Orders_Raw!B:B),Customers_Raw!A:A,Customers_Raw!E:E) -> Consumer | N18: =IF(COUNTIF($A$2:A18,A18)=1,1,0) -> 1
A19: O52314 | B19: P1005 | C19: 4 | D19: 30423.76 | E19: =_xlfn.XLOOKUP(Order_Items_Raw!B236,Products_Raw!A:A,Products_Raw!D:D) -> 5412.91 | F19: =D19-(C19*E19) -> 8772.12 | G19: =PROPER(TRIM(CLEAN(_xlfn.XLOOKUP(Order_Items_Raw!A236,Orders_Raw!A:A,Orders_Raw!E:E)))) -> Marketplace | H19: =_xlfn.XLOOKUP(B19,Products_Raw!A:A,Products_Raw!C:C) -> Sports | I19: =_xlfn.XLOOKUP(_xlfn.XLOOKUP(A19,Orders_Raw!A:A,Orders_Raw!B:B),Customers_Raw!A:A,Customers_Raw!E:E) -> Corporate | J19: =_xlfn.XLOOKUP(Order_Items_Raw!A236,Orders_Raw!A:A,Orders_Raw!C:C) -> 45773 | K19: Apr | L19: =_xlfn.XLOOKUP(A19,Orders_Raw!A:A,Orders_Raw!D:D) -> Processing | M19: =_xlfn.XLOOKUP(_xlfn.XLOOKUP(A19,Orders_Raw!A:A,Orders_Raw!B:B),Customers_Raw!A:A,Customers_Raw!E:E) -> Corporate | N19: =IF(COUNTIF($A$2:A19,A19)=1,1,0) -> 1
A20: O50095 | B20: P1006 | C20: 2 | D20: 31478.26 | E20: =_xlfn.XLOOKUP(Order_Items_Raw!B240,Products_Raw!A:A,Products_Raw!D:D) -> 5412.91 | F20: =D20-(C20*E20) -> 20652.44 | G20: =PROPER(TRIM(CLEAN(_xlfn.XLOOKUP(Order_Items_Raw!A240,Orders_Raw!A:A,Orders_Raw!E:E)))) -> Website | H20: =_xlfn.XLOOKUP(B20,Products_Raw!A:A,Products_Raw!C:C) -> Electronics | I20: =_xlfn.XLOOKUP(_xlfn.XLOOKUP(A20,Orders_Raw!A:A,Orders_Raw!B:B),Customers_Raw!A:A,Customers_Raw!E:E) -> Corporate | J20: =_xlfn.XLOOKUP(Order_Items_Raw!A240,Orders_Raw!A:A,Orders_Raw!C:C) -> 45751 | K20: Apr | L20: =_xlfn.XLOOKUP(A20,Orders_Raw!A:A,Orders_Raw!D:D) -> Cancelled | M20: =_xlfn.XLOOKUP(_xlfn.XLOOKUP(A20,Orders_Raw!A:A,Orders_Raw!B:B),Customers_Raw!A:A,Customers_Raw!E:E) -> Corporate | N20: =IF(COUNTIF($A$2:A20,A20)=1,1,0) -> 1
A21: O50165 | B21: P1006 | C21: 1 | D21: 12976.25 | E21: =_xlfn.XLOOKUP(Order_Items_Raw!B242,Products_Raw!A:A,Products_Raw!D:D) -> 5412.91 | F21: =D21-(C21*E21) -> 7563.34 | G21: =PROPER(TRIM(CLEAN(_xlfn.XLOOKUP(Order_Items_Raw!A242,Orders_Raw!A:A,Orders_Raw!E:E)))) -> Mobile App | H21: =_xlfn.XLOOKUP(B21,Products_Raw!A:A,Products_Raw!C:C) -> Electronics | I21: =_xlfn.XLOOKUP(_xlfn.XLOOKUP(A21,Orders_Raw!A:A,Orders_Raw!B:B),Customers_Raw!A:A,Customers_Raw!E:E) -> Consumer | J21: =_xlfn.XLOOKUP(Order_Items_Raw!A242,Orders_Raw!A:A,Orders_Raw!C:C) -> 45776 | K21: Apr | L21: =_xlfn.XLOOKUP(A21,Orders_Raw!A:A,Orders_Raw!D:D) -> Delivered | M21: =_xlfn.XLOOKUP(_xlfn.XLOOKUP(A21,Orders_Raw!A:A,Orders_Raw!B:B),Customers_Raw!A:A,Customers_Raw!E:E) -> Consumer | N21: =IF(COUNTIF($A$2:A21,A21)=1,1,0) -> 1
A22: O51913 | B22: P1006 | C22: 4 | D22: 55018.66 | E22: =_xlfn.XLOOKUP(Order_Items_Raw!B268,Products_Raw!A:A,Products_Raw!D:D) -> 11653.29 | F22: =D22-(C22*E22) -> 8405.5 | G22: =PROPER(TRIM(CLEAN(_xlfn.XLOOKUP(Order_Items_Raw!A268,Orders_Raw!A:A,Orders_Raw!E:E)))) -> Website | H22: =_xlfn.XLOOKUP(B22,Products_Raw!A:A,Products_Raw!C:C) -> Electronics | I22: =_xlfn.XLOOKUP(_xlfn.XLOOKUP(A22,Orders_Raw!A:A,Orders_Raw!B:B),Customers_Raw!A:A,Customers_Raw!E:E) -> Consumer | J22: =_xlfn.XLOOKUP(Order_Items_Raw!A268,Orders_Raw!A:A,Orders_Raw!C:C) -> 45766 | K22: Apr | L22: =_xlfn.XLOOKUP(A22,Orders_Raw!A:A,Orders_Raw!D:D) -> Delivered | M22: =_xlfn.XLOOKUP(_xlfn.XLOOKUP(A22,Orders_Raw!A:A,Orders_Raw!B:B),Customers_Raw!A:A,Customers_Raw!E:E) -> Consumer | N22: =IF(COUNTIF($A$2:A22,A22)=1,1,0) -> 1
A23: O52296 | B23: P1006 | C23: 2 | D23: 25394.77 | E23: =_xlfn.XLOOKUP(Order_Items_Raw!B277,Products_Raw!A:A,Products_Raw!D:D) -> 11764.29 | F23: =D23-(C23*E23) -> 1866.19 | G23: =PROPER(TRIM(CLEAN(_xlfn.XLOOKUP(Order_Items_Raw!A277,Orders_Raw!A:A,Orders_Raw!E:E)))) -> Mobile App | H23: =_xlfn.XLOOKUP(B23,Products_Raw!A:A,Products_Raw!C:C) -> Electronics | I23: =_xlfn.XLOOKUP(_xlfn.XLOOKUP(A23,Orders_Raw!A:A,Orders_Raw!B:B),Customers_Raw!A:A,Customers_Raw!E:E) -> Consumer | J23: =_xlfn.XLOOKUP(Order_Items_Raw!A277,Orders_Raw!A:A,Orders_Raw!C:C) -> 45760 | K23: Apr | L23: =_xlfn.XLOOKUP(A23,Orders_Raw!A:A,Orders_Raw!D:D) -> Processing | M23: =_xlfn.XLOOKUP(_xlfn.XLOOKUP(A23,Orders_Raw!A:A,Orders_Raw!B:B),Customers_Raw!A:A,Customers_Raw!E:E) -> Consumer | N23: =IF(COUNTIF($A$2:A23,A23)=1,1,0) -> 1
A24: O50871 | B24: P1007 | C24: 3 | D24: 30108.57 | E24: =_xlfn.XLOOKUP(Order_Items_Raw!B296,Products_Raw!A:A,Products_Raw!D:D) -> 10086.81 | F24: =D24-(C24*E24) -> -151.86 | G24: =PROPER(TRIM(CLEAN(_xlfn.XLOOKUP(Order_Items_Raw!A296,Orders_Raw!A:A,Orders_Raw!E:E)))) -> Mobile App | H24: =_xlfn.XLOOKUP(B24,Products_Raw!A:A,Products_Raw!C:C) -> Sports | I24: =_xlfn.XLOOKUP(_xlfn.XLOOKUP(A24,Orders_Raw!A:A,Orders_Raw!B:B),Customers_Raw!A:A,Customers_Raw!E:E) -> Consumer | J24: =_xlfn.XLOOKUP(Order_Items_Raw!A296,Orders_Raw!A:A,Orders_Raw!C:C) -> 45758 | K24: Apr | L24: =_xlfn.XLOOKUP(A24,Orders_Raw!A:A,Orders_Raw!D:D) -> Shipped | M24: =_xlfn.XLOOKUP(_xlfn.XLOOKUP(A24,Orders_Raw!A:A,Orders_Raw!B:B),Customers_Raw!A:A,Customers_Raw!E:E) -> Consumer | N24: =IF(COUNTIF($A$2:A24,A24)=1,1,0) -> 0
A25: O51082 | B25: P1007 | C25: 4 | D25: 35924.35 | E25: =_xlfn.XLOOKUP(Order_Items_Raw!B304,Products_Raw!A:A,Products_Raw!D:D) -> 9947.76 | F25: =D25-(C25*E25) -> -3866.69 | G25: =PROPER(TRIM(CLEAN(_xlfn.XLOOKUP(Order_Items_Raw!A304,Orders_Raw!A:A,Orders_Raw!E:E)))) -> Mobile App | H25: =_xlfn.XLOOKUP(B25,Products_Raw!A:A,Products_Raw!C:C) -> Sports | I25: =_xlfn.XLOOKUP(_xlfn.XLOOKUP(A25,Orders_Raw!A:A,Orders_Raw!B:B),Customers_Raw!A:A,Customers_Raw!E:E) -> Consumer | J25: =_xlfn.XLOOKUP(Order_Items_Raw!A304,Orders_Raw!A:A,Orders_Raw!C:C) -> 45758 | K25: Apr | L25: =_xlfn.XLOOKUP(A25,Orders_Raw!A:A,Orders_Raw!D:D) -> Delivered | M25: =_xlfn.XLOOKUP(_xlfn.XLOOKUP(A25,Orders_Raw!A:A,Orders_Raw!B:B),Customers_Raw!A:A,Customers_Raw!E:E) -> Consumer | N25: =IF(COUNTIF($A$2:A25,A25)=1,1,0) -> 1
A26: O50611 | B26: P1009 | C26: 4 | D26: 23277.91 | E26: =_xlfn.XLOOKUP(Order_Items_Raw!B388,Products_Raw!A:A,Products_Raw!D:D) -> 295.87 | F26: =D26-(C26*E26) -> 22094.43 | G26: =PROPER(TRIM(CLEAN(_xlfn.XLOOKUP(Order_Items_Raw!A388,Orders_Raw!A:A,Orders_Raw!E:E)))) -> Website | H26: =_xlfn.XLOOKUP(B26,Products_Raw!A:A,Products_Raw!C:C) -> Beauty | I26: =_xlfn.XLOOKUP(_xlfn.XLOOKUP(A26,Orders_Raw!A:A,Orders_Raw!B:B),Customers_Raw!A:A,Customers_Raw!E:E) -> Consumer | J26: =_xlfn.XLOOKUP(Order_Items_Raw!A388,Orders_Raw!A:A,Orders_Raw!C:C) -> 45886 | K26: Aug | L26: =_xlfn.XLOOKUP(A26,Orders_Raw!A:A,Orders_Raw!D:D) -> Delivered | M26: =_xlfn.XLOOKUP(_xlfn.XLOOKUP(A26,Orders_Raw!A:A,Orders_Raw!B:B),Customers_Raw!A:A,Customers_Raw!E:E) -> Consumer | N26: =IF(COUNTIF($A$2:A26,A26)=1,1,0) -> 1
A27: O51045 | B27: P1009 | C27: 3 | D27: 20547.71 | E27: =_xlfn.XLOOKUP(Order_Items_Raw!B395,Products_Raw!A:A,Products_Raw!D:D) -> 295.87 | F27: =D27-(C27*E27) -> 19660.1 | G27: =PROPER(TRIM(CLEAN(_xlfn.XLOOKUP(Order_Items_Raw!A395,Orders_Raw!A:A,Orders_Raw!E:E)))) -> Website | H27: =_xlfn.XLOOKUP(B27,Products_Raw!A:A,Products_Raw!C:C) -> Beauty | I27: =_xlfn.XLOOKUP(_xlfn.XLOOKUP(A27,Orders_Raw!A:A,Orders_Raw!B:B),Customers_Raw!A:A,Customers_Raw!E:E) -> Consumer | J27: =_xlfn.XLOOKUP(Order_Items_Raw!A395,Orders_Raw!A:A,Orders_Raw!C:C) -> 45894 | K27: Aug | L27: =_xlfn.XLOOKUP(A27,Orders_Raw!A:A,Orders_Raw!D:D) -> Delivered | M27: =_xlfn.XLOOKUP(_xlfn.XLOOKUP(A27,Orders_Raw!A:A,Orders_Raw!B:B),Customers_Raw!A:A,Customers_Raw!E:E) -> Consumer | N27: =IF(COUNTIF($A$2:A27,A27)=1,1,0) -> 1
A28: O51194 | B28: P1009 | C28: 1 | D28: 6055.99 | E28: =_xlfn.XLOOKUP(Order_Items_Raw!B400,Products_Raw!A:A,Products_Raw!D:D) -> 474.93 | F28: =D28-(C28*E28) -> 5581.06 | G28: =PROPER(TRIM(CLEAN(_xlfn.XLOOKUP(Order_Items_Raw!A400,Orders_Raw!A:A,Orders_Raw!E:E)))) -> Website | H28: =_xlfn.XLOOKUP(B28,Products_Raw!A:A,Products_Raw!C:C) -> Beauty | I28: =_xlfn.XLOOKUP(_xlfn.XLOOKUP(A28,Orders_Raw!A:A,Orders_Raw!B:B),Customers_Raw!A:A,Customers_Raw!E:E) -> Corporate | J28: =_xlfn.XLOOKUP(Order_Items_Raw!A400,Orders_Raw!A:A,Orders_Raw!C:C) -> 45888 | K28: Aug | L28: =_xlfn.XLOOKUP(A28,Orders_Raw!A:A,Orders_Raw!D:D) -> Delivered | M28: =_xlfn.XLOOKUP(_xlfn.XLOOKUP(A28,Orders_Raw!A:A,Orders_Raw!B:B),Customers_Raw!A:A,Customers_Raw!E:E) -> Corporate | N28: =IF(COUNTIF($A$2:A28,A28)=1,1,0) -> 1
A29: O50337 | B29: P1010 | C29: 1 | D29: 7902.31 | E29: =_xlfn.XLOOKUP(Order_Items_Raw!B428,Products_Raw!A:A,Products_Raw!D:D) -> 7802.03 | F29: =D29-(C29*E29) -> 100.28 | G29: =PROPER(TRIM(CLEAN(_xlfn.XLOOKUP(Order_Items_Raw!A428,Orders_Raw!A:A,Orders_Raw!E:E)))) -> Marketplace | H29: =_xlfn.XLOOKUP(B29,Products_Raw!A:A,Products_Raw!C:C) -> Home & Kitchen | I29: =_xlfn.XLOOKUP(_xlfn.XLOOKUP(A29,Orders_Raw!A:A,Orders_Raw!B:B),Customers_Raw!A:A,Customers_Raw!E:E) -> Small Business | J29: =_xlfn.XLOOKUP(Order_Items_Raw!A428,Orders_Raw!A:A,Orders_Raw!C:C) -> 45883 | K29: Aug | L29: =_xlfn.XLOOKUP(A29,Orders_Raw!A:A,Orders_Raw!D:D) -> Delivered | M29: =_xlfn.XLOOKUP(_xlfn.XLOOKUP(A29,Orders_Raw!A:A,Orders_Raw!B:B),Customers_Raw!A:A,Customers_Raw!E:E) -> Small Business | N29: =IF(COUNTIF($A$2:A29,A29)=1,1,0) -> 1
A30: O50462 | B30: P1010 | C30: 4 | D30: 34520.55 | E30: =_xlfn.XLOOKUP(Order_Items_Raw!B431,Products_Raw!A:A,Products_Raw!D:D) -> 680.62 | F30: =D30-(C30*E30) -> 31798.07 | G30: =PROPER(TRIM(CLEAN(_xlfn.XLOOKUP(Order_Items_Raw!A431,Orders_Raw!A:A,Orders_Raw!E:E)))) -> Website | H30: =_xlfn.XLOOKUP(B30,Products_Raw!A:A,Products_Raw!C:C) -> Home & Kitchen | I30: =_xlfn.XLOOKUP(_xlfn.XLOOKUP(A30,Orders_Raw!A:A,Orders_Raw!B:B),Customers_Raw!A:A,Customers_Raw!E:E) -> Small Business | J30: =_xlfn.XLOOKUP(Order_Items_Raw!A431,Orders_Raw!A:A,Orders_Raw!C:C) -> 45886 | K30: Aug | L30: =_xlfn.XLOOKUP(A30,Orders_Raw!A:A,Orders_Raw!D:D) -> Shipped | M30: =_xlfn.XLOOKUP(_xlfn.XLOOKUP(A30,Orders_Raw!A:A,Orders_Raw!B:B),Customers_Raw!A:A,Customers_Raw!E:E) -> Small Business | N30: =IF(COUNTIF($A$2:A30,A30)=1,1,0) -> 1
A31: O51410 | B31: P1010 | C31: 3 | D31: 19236.47 | E31: =_xlfn.XLOOKUP(Order_Items_Raw!B449,Products_Raw!A:A,Products_Raw!D:D) -> 4640.09 | F31: =D31-(C31*E31) -> 5316.2 | G31: =PROPER(TRIM(CLEAN(_xlfn.XLOOKUP(Order_Items_Raw!A449,Orders_Raw!A:A,Orders_Raw!E:E)))) -> Website | H31: =_xlfn.XLOOKUP(B31,Products_Raw!A:A,Products_Raw!C:C) -> Home & Kitchen | I31: =_xlfn.XLOOKUP(_xlfn.XLOOKUP(A31,Orders_Raw!A:A,Orders_Raw!B:B),Customers_Raw!A:A,Customers_Raw!E:E) -> Consumer | J31: =_xlfn.XLOOKUP(Order_Items_Raw!A449,Orders_Raw!A:A,Orders_Raw!C:C) -> 45900 | K31: Aug | L31: =_xlfn.XLOOKUP(A31,Orders_Raw!A:A,Orders_Raw!D:D) -> Processing | M31: =_xlfn.XLOOKUP(_xlfn.XLOOKUP(A31,Orders_Raw!A:A,Orders_Raw!B:B),Customers_Raw!A:A,Customers_Raw!E:E) -> Consumer | N31: =IF(COUNTIF($A$2:A31,A31)=1,1,0) -> 1
A32: O51690 | B32: P1010 | C32: 1 | D32: 6688.83 | E32: =_xlfn.XLOOKUP(Order_Items_Raw!B455,Products_Raw!A:A,Products_Raw!D:D) -> 229.52 | F32: =D32-(C32*E32) -> 6459.31 | G32: =PROPER(TRIM(CLEAN(_xlfn.XLOOKUP(Order_Items_Raw!A455,Orders_Raw!A:A,Orders_Raw!E:E)))) -> Marketplace | H32: =_xlfn.XLOOKUP(B32,Products_Raw!A:A,Products_Raw!C:C) -> Home & Kitchen | I32: =_xlfn.XLOOKUP(_xlfn.XLOOKUP(A32,Orders_Raw!A:A,Orders_Raw!B:B),Customers_Raw!A:A,Customers_Raw!E:E) -> Consumer | J32: =_xlfn.XLOOKUP(Order_Items_Raw!A455,Orders_Raw!A:A,Orders_Raw!C:C) -> 45897 | K32: Aug | L32: =_xlfn.XLOOKUP(A32,Orders_Raw!A:A,Orders_Raw!D:D) -> Shipped | M32: =_xlfn.XLOOKUP(_xlfn.XLOOKUP(A32,Orders_Raw!A:A,Orders_Raw!B:B),Customers_Raw!A:A,Customers_Raw!E:E) -> Consumer | N32: =IF(COUNTIF($A$2:A32,A32)=1,1,0) -> 1
A33: O50407 | B33: P1011 | C33: 3 | D33: 30937.85 | E33: =_xlfn.XLOOKUP(Order_Items_Raw!B476,Products_Raw!A:A,Products_Raw!D:D) -> 6443.36 | F33: =D33-(C33*E33) -> 11607.77 | G33: =PROPER(TRIM(CLEAN(_xlfn.XLOOKUP(Order_Items_Raw!A476,Orders_Raw!A:A,Orders_Raw!E:E)))) -> Website | H33: =_xlfn.XLOOKUP(B33,Products_Raw!A:A,Products_Raw!C:C) -> Sports | I33: =_xlfn.XLOOKUP(_xlfn.XLOOKUP(A33,Orders_Raw!A:A,Orders_Raw!B:B),Customers_Raw!A:A,Customers_Raw!E:E) -> Consumer | J33: =_xlfn.XLOOKUP(Order_Items_Raw!A476,Orders_Raw!A:A,Orders_Raw!C:C) -> 45896 | K33: Aug | L33: =_xlfn.XLOOKUP(A33,Orders_Raw!A:A,Orders_Raw!D:D) -> Delivered | M33: =_xlfn.XLOOKUP(_xlfn.XLOOKUP(A33,Orders_Raw!A:A,Orders_Raw!B:B),Customers_Raw!A:A,Customers_Raw!E:E) -> Consumer | N33: =IF(COUNTIF($A$2:A33,A33)=1,1,0) -> 1
A34: O51403 | B34: P1011 | C34: 1 | D34: 8446.75 | E34: =_xlfn.XLOOKUP(Order_Items_Raw!B502,Products_Raw!A:A,Products_Raw!D:D) -> 11668.5 | F34: =D34-(C34*E34) -> -3221.75 | G34: =PROPER(TRIM(CLEAN(_xlfn.XLOOKUP(Order_Items_Raw!A502,Orders_Raw!A:A,Orders_Raw!E:E)))) -> Mobile App | H34: =_xlfn.XLOOKUP(B34,Products_Raw!A:A,Products_Raw!C:C) -> Sports | I34: =_xlfn.XLOOKUP(_xlfn.XLOOKUP(A34,Orders_Raw!A:A,Orders_Raw!B:B),Customers_Raw!A:A,Customers_Raw!E:E) -> Consumer | J34: =_xlfn.XLOOKUP(Order_Items_Raw!A502,Orders_Raw!A:A,Orders_Raw!C:C) -> 45887 | K34: Aug | L34: =_xlfn.XLOOKUP(A34,Orders_Raw!A:A,Orders_Raw!D:D) -> Delivered | M34: =_xlfn.XLOOKUP(_xlfn.XLOOKUP(A34,Orders_Raw!A:A,Orders_Raw!B:B),Customers_Raw!A:A,Customers_Raw!E:E) -> Consumer | N34: =IF(COUNTIF($A$2:A34,A34)=1,1,0) -> 1
A35: O50565 | B35: P1012 | C35: 3 | D35: 36246.91 | E35: =_xlfn.XLOOKUP(Order_Items_Raw!B531,Products_Raw!A:A,Products_Raw!D:D) -> 11118.8 | F35: =D35-(C35*E35) -> 2890.51 | G35: =PROPER(TRIM(CLEAN(_xlfn.XLOOKUP(Order_Items_Raw!A531,Orders_Raw!A:A,Orders_Raw!E:E)))) -> Website | H35: =_xlfn.XLOOKUP(B35,Products_Raw!A:A,Products_Raw!C:C) -> Electronics | I35: =_xlfn.XLOOKUP(_xlfn.XLOOKUP(A35,Orders_Raw!A:A,Orders_Raw!B:B),Customers_Raw!A:A,Customers_Raw!E:E) -> Corporate | J35: =_xlfn.XLOOKUP(Order_Items_Raw!A531,Orders_Raw!A:A,Orders_Raw!C:C) -> 45885 | K35: Aug | L35: =_xlfn.XLOOKUP(A35,Orders_Raw!A:A,Orders_Raw!D:D) -> Shipped | M35: =_xlfn.XLOOKUP(_xlfn.XLOOKUP(A35,Orders_Raw!A:A,Orders_Raw!B:B),Customers_Raw!A:A,Customers_Raw!E:E) -> Corporate | N35: =IF(COUNTIF($A$2:A35,A35)=1,1,0) -> 1
A36: O50633 | B36: P1012 | C36: 3 | D36: 40026.98 | E36: =_xlfn.XLOOKUP(Order_Items_Raw!B533,Products_Raw!A:A,Products_Raw!D:D) -> 5057.68 | F36: =D36-(C36*E36) -> 24853.94 | G36: =PROPER(TRIM(CLEAN(_xlfn.XLOOKUP(Order_Items_Raw!A533,Orders_Raw!A:A,Orders_Raw!E:E)))) -> Mobile App | H36: =_xlfn.XLOOKUP(B36,Products_Raw!A:A,Products_Raw!C:C) -> Electronics | I36: =_xlfn.XLOOKUP(_xlfn.XLOOKUP(A36,Orders_Raw!A:A,Orders_Raw!B:B),Customers_Raw!A:A,Customers_Raw!E:E) -> Corporate | J36: =_xlfn.XLOOKUP(Order_Items_Raw!A533,Orders_Raw!A:A,Orders_Raw!C:C) -> 45895 | K36: Aug | L36: =_xlfn.XLOOKUP(A36,Orders_Raw!A:A,Orders_Raw!D:D) -> Delivered | M36: =_xlfn.XLOOKUP(_xlfn.XLOOKUP(A36,Orders_Raw!A:A,Orders_Raw!B:B),Customers_Raw!A:A,Customers_Raw!E:E) -> Corporate | N36: =IF(COUNTIF($A$2:A36,A36)=1,1,0) -> 1
A37: O51129 | B37: P1012 | C37: 1 | D37: 14657.97 | E37: =_xlfn.XLOOKUP(Order_Items_Raw!B542,Products_Raw!A:A,Products_Raw!D:D) -> 1892.68 | F37: =D37-(C37*E37) -> 12765.29 | G37: =PROPER(TRIM(CLEAN(_xlfn.XLOOKUP(Order_Items_Raw!A542,Orders_Raw!A:A,Orders_Raw!E:E)))) -> Mobile App | H37: =_xlfn.XLOOKUP(B37,Products_Raw!A:A,Products_Raw!C:C) -> Electronics | I37: =_xlfn.XLOOKUP(_xlfn.XLOOKUP(A37,Orders_Raw!A:A,Orders_Raw!B:B),Customers_Raw!A:A,Customers_Raw!E:E) -> Corporate | J37: =_xlfn.XLOOKUP(Order_Items_Raw!A542,Orders_Raw!A:A,Orders_Raw!C:C) -> 45876 | K37: Aug | L37: =_xlfn.XLOOKUP(A37,Orders_Raw!A:A,Orders_Raw!D:D) -> Delivered | M37: =_xlfn.XLOOKUP(_xlfn.XLOOKUP(A37,Orders_Raw!A:A,Orders_Raw!B:B),Customers_Raw!A:A,Customers_Raw!E:E) -> Corporate | N37: =IF(COUNTIF($A$2:A37,A37)=1,1,0) -> 1
A38: O51425 | B38: P1012 | C38: 2 | D38: 24755.1 | E38: =_xlfn.XLOOKUP(Order_Items_Raw!B550,Products_Raw!A:A,Products_Raw!D:D) -> 5931.04 | F38: =D38-(C38*E38) -> 12893.02 | G38: =PROPER(TRIM(CLEAN(_xlfn.XLOOKUP(Order_Items_Raw!A550,Orders_Raw!A:A,Orders_Raw!E:E)))) -> Marketplace | H38: =_xlfn.XLOOKUP(B38,Products_Raw!A:A,Products_Raw!C:C) -> Electronics | I38: =_xlfn.XLOOKUP(_xlfn.XLOOKUP(A38,Orders_Raw!A:A,Orders_Raw!B:B),Customers_Raw!A:A,Customers_Raw!E:E) -> Consumer | J38: =_xlfn.XLOOKUP(Order_Items_Raw!A550,Orders_Raw!A:A,Orders_Raw!C:C) -> 45893 | K38: Aug | L38: =_xlfn.XLOOKUP(A38,Orders_Raw!A:A,Orders_Raw!D:D) -> Shipped | M38: =_xlfn.XLOOKUP(_xlfn.XLOOKUP(A38,Orders_Raw!A:A,Orders_Raw!B:B),Customers_Raw!A:A,Customers_Raw!E:E) -> Consumer | N38: =IF(COUNTIF($A$2:A38,A38)=1,1,0) -> 1
A39: O51717 | B39: P1012 | C39: 1 | D39: 10979.75 | E39: =_xlfn.XLOOKUP(Order_Items_Raw!B558,Products_Raw!A:A,Products_Raw!D:D) -> 4539.2 | F39: =D39-(C39*E39) -> 6440.55 | G39: =PROPER(TRIM(CLEAN(_xlfn.XLOOKUP(Order_Items_Raw!A558,Orders_Raw!A:A,Orders_Raw!E:E)))) -> Website | H39: =_xlfn.XLOOKUP(B39,Products_Raw!A:A,Products_Raw!C:C) -> Electronics | I39: =_xlfn.XLOOKUP(_xlfn.XLOOKUP(A39,Orders_Raw!A:A,Orders_Raw!B:B),Customers_Raw!A:A,Customers_Raw!E:E) -> Corporate | J39: =_xlfn.XLOOKUP(Order_Items_Raw!A558,Orders_Raw!A:A,Orders_Raw!C:C) -> 45878 | K39: Aug | L39: =_xlfn.XLOOKUP(A39,Orders_Raw!A:A,Orders_Raw!D:D) -> Shipped | M39: =_xlfn.XLOOKUP(_xlfn.XLOOKUP(A39,Orders_Raw!A:A,Orders_Raw!B:B),Customers_Raw!A:A,Customers_Raw!E:E) -> Corporate | N39: =IF(COUNTIF($A$2:A39,A39)=1,1,0) -> 0
A40: O51913 | B40: P1012 | C40: 4 | D40: 44612.51 | E40: =_xlfn.XLOOKUP(Order_Items_Raw!B560,Products_Raw!A:A,Products_Raw!D:D) -> 4591.42 | F40: =D40-(C40*E40) -> 26246.83 | G40: =PROPER(TRIM(CLEAN(_xlfn.XLOOKUP(Order_Items_Raw!A560,Orders_Raw!A:A,Orders_Raw!E:E)))) -> Mobile App | H40: =_xlfn.XLOOKUP(B40,Products_Raw!A:A,Products_Raw!C:C) -> Electronics | I40: =_xlfn.XLOOKUP(_xlfn.XLOOKUP(A40,Orders_Raw!A:A,Orders_Raw!B:B),Customers_Raw!A:A,Customers_Raw!E:E) -> Consumer | J40: =_xlfn.XLOOKUP(Order_Items_Raw!A560,Orders_Raw!A:A,Orders_Raw!C:C) -> 45877 | K40: Aug | L40: =_xlfn.XLOOKUP(A40,Orders_Raw!A:A,Orders_Raw!D:D) -> Delivered | M40: =_xlfn.XLOOKUP(_xlfn.XLOOKUP(A40,Orders_Raw!A:A,Orders_Raw!B:B),Customers_Raw!A:A,Customers_Raw!E:E) -> Consumer | N40: =IF(COUNTIF($A$2:A40,A40)=1,1,0) -> 0
...

Sheet Returns_Raw
A1: Return_ID | B1: Order_ID | C1: Return_Reason | D1: Refund_Amount
A2: R70001 | B2: O52259 | C2: Wrong Product | D2: 3586.57
A3: R70002 | B3: O51727 | C3: Customer Changed Mind | D3: 62953.3
A4: R70003 | B4: O52468 | C4: Quality Issue | D4: 10785.04
A5: R70004 | B5: O52004 | C5: Damaged | D5: 6574.48
A6: R70005 | B6: O52418 | C6: Damaged | D6: 37099.29
A7: R70006 | B7: O51194 | C7: Late Delivery | D7: 5729.31
A8: R70007 | B8: O51982 | C8: Customer Changed Mind | D8: 60483.17
A9: R70008 | B9: O52184 | C9: Wrong Product | D9: 4641.09
A10: R70009 | B10: O52096 | C10: Wrong Product | D10: 22113.41
A11: R70010 | B11: O50294 | C11: Customer Changed Mind | D11: 27284.51
A12: R70011 | B12: O52399 | C12: Customer Changed Mind | D12: 20370.32
A13: R70012 | B13: O51315 | C13: Customer Changed Mind | D13: 38797.69
... A175: R70174 | B175: O51307 | C175: Customer Changed Mind | D175: 27918.93

Sheet Products_Raw
A1: Product_ID | B1: Product_Name | C1: Category | D1: Unit_Cost
A2: P1001 | B2: Premium Headphones P1001 | C2: Sports | D2: 4740.6
A3: P1002 | B3: Essential Mixer P1002 | C3: Sports | D3: 10244.32
A4: P1003 | B4: Eco Notebook P1003 | C4: Sports | D4: 4936.19
A5: P1004 | B5: Pro Mouse P1004 | C5: Beauty | D5: 1069.73
A6: P1005 | B6: Premium Notebook P1005 | C6: Sports | D6: 6579.03
A7: P1006 | B7: Eco Monitor P1006 | C7: Electronics | D7: 10361.65
A8: P1007 | B8: Premium Keyboard P1007 | C8: Sports | D8: 7144.88
A9: P1008 | B9: Smart Keyboard P1008 | C9: Home & Kitchen | D9: 2831.41
A10: P1009 | B10: Essential Shoes P1009 | C10: Beauty | D10: 4703.24
A11: P1010 | B11: Classic Mixer P1010 | C11: Home & Kitchen | D11: 5483.96
A12: P1011 | B12: Pro Monitor P1011 | C12: Sports | D12: 7014.31
A13: P1012 | B13: Eco Mixer P1012 | C13: Electronics | D13: 9148.31
... A81: P1080 | B81: Essential Shoes P1080 | C81: Beauty | D81: 2935.19

Sheet Returns pivot
A3: Return_Reason | B3: Sum of Refund_Amount | D3: Count of Refund_Amount
A4: Customer Changed Mind | B4: 1029221.2 | D4: 174
A5: Damaged | B5: 491045.15
A6: Late Delivery | B6: 798832.91 | D6: Return Rate
A7: Quality Issue | B7: 721552.3 | D7: =GETPIVOTDATA("Refund_Amount",$D$3)/Dashboard_Pivots!C46 -> 0.046350559
A8: Wrong Product | B8: 718051.53
A9: Grand Total | B9: 3758703.1

Sheet Dashboard_Pivots
A1: Sales_Channel | B1: Sum of Line_Revenue | D1: Category | E1: Sum of Line_Revenue
A2: Marketplace | B2: 14631195 | D2: Beauty | E2: 8462473.1
A3: Mobile App | B3: 26676534 | D3: Electronics | E3: 13975356
A4: Website | B4: 34202096 | D4: Fashion | E4: 10985690
A5: Grand Total | B5: 75509825 | D5: Home & Kitchen | E5: 13519711
D6: Office Supplies | E6: 12320846
A7: Customer_Segment | B7: Sum of Line_Revenue | D7: Sports | E7: 16245748
A8: Consumer | B8: 45586560 | D8: Grand Total | E8: 75509825 | G8: =GETPIVOTDATA("Line_Revenue",$A$1) -> 75509825
A9: Corporate | B9: 20134522
A10: Small Business | B10: 9788743
A11: Grand Total | B11: 75509825
A13: Category | B13: Sum of Gross_Profit | D13: Order_Month | E13: Sum of Gross_Profit
A14: Beauty | B14: 207271.33 | D14: Jan | E14: 1370472
A15: Electronics | B15: 3380811.5 | D15: Feb | E15: 1058395.8
A16: Fashion | B16: 3560057.3 | D16: Mar | E16: 654117.06
A17: Home & Kitchen | B17: 3674266.8 | D17: Apr | E17: 2713319.2
A18: Office Supplies | B18: 4818784.1 | D18: May | E18: 2361286.4
A19: Sports | B19: 5673035.6 | D19: Jun | E19: 2674015.7
A20: Grand Total | B20: 21314226 | D20: Jul | E20: 2382891.1
D21: Aug | E21: 2368936
D22: Sep | E22: 1584602.8
D23: Oct | E23: 2923265.8
D24: Nov | E24: 1841479.3
A25: Total Revenue | D25: Dec | E25: -618554.58
A26: 75509825 | D26: Grand Total | E26: 21314226
A28: Total Units Sold | G28: =GETPIVOTDATA("Gross_Profit",$A$31) -> 21314226
A29: 9419
A31: Total Gross Profit
A32: 21314226 | C32: Average Order Value
C33: =GETPIVOTDATA("Line_Revenue",$A$25)/GETPIVOTDATA("Order_ID",$C$44) -> 20114.498
C35: Gross Margin
C36: =GETPIVOTDATA("Gross_Profit",$A$31)/GETPIVOTDATA("Line_Revenue",$A$25) -> 0.2822709
C44: Count of Order_ID
C45: 3754
C46: =GETPIVOTDATA("Order_ID",$C$44) -> 3754

Sheet Dashboard
